<mujoco model="bumi3.0">
  <compiler angle="radian" meshdir="../meshes/"/>

  <default>
    <joint damping="0.001" armature="0.03" frictionloss="0.1"/>
  </default>

  <asset>
    <texture type="skybox" builtin="gradient" rgb1="0.3 0.5 0.7" rgb2="0 0 0" width="512" height="512"/>
    <texture name="texplane" type="2d" builtin="checker" rgb1=".2 .3 .4" rgb2=".1 0.15 0.2" width="512" height="512" mark="cross" markrgb=".8 .8 .8"/>
    <material name="matplane" reflectance="0." texture="texplane" texrepeat="1 1" texuniform="true"/>

    <mesh name="base_link" file="base_link.STL"/>
    <mesh name="waist_yaw_link" file="waist_yaw_link.STL"/>
    <mesh name="l_arm_pitch_link" file="l_arm_pitch_link.STL"/>
    <mesh name="l_arm_roll_link" file="l_arm_roll_link.STL"/>
    <mesh name="l_arm_yaw_link" file="l_arm_yaw_link.STL"/>
    <mesh name="l_elbow_pitch_link" file="l_elbow_pitch_link.STL"/>
    <mesh name="r_arm_pitch_link" file="r_arm_pitch_link.STL"/>
    <mesh name="r_arm_roll_link" file="r_arm_roll_link.STL"/>
    <mesh name="r_arm_yaw_link" file="r_arm_yaw_link.STL"/>
    <mesh name="r_elbow_pitch_link" file="r_elbow_pitch_link.STL"/>
    <mesh name="l_leg_pitch_link" file="l_leg_pitch_link.STL"/>
    <mesh name="l_leg_roll_link" file="l_leg_roll_link.STL"/>
    <mesh name="l_leg_yaw_link" file="l_leg_yaw_link.STL"/>
    <mesh name="l_knee_pitch_link" file="l_knee_pitch_link.STL"/>
    <mesh name="l_ankle_pitch_link" file="l_ankle_pitch_link.STL"/>
    <mesh name="l_ankle_roll_link" file="l_ankle_roll_link.STL"/>
    <mesh name="r_leg_pitch_link" file="r_leg_pitch_link.STL"/>
    <mesh name="r_leg_roll_link" file="r_leg_roll_link.STL"/>
    <mesh name="r_leg_yaw_link" file="r_leg_yaw_link.STL"/>
    <mesh name="r_knee_pitch_link" file="r_knee_pitch_link.STL"/>
    <mesh name="r_ankle_pitch_link" file="r_ankle_pitch_link.STL"/>
    <mesh name="r_ankle_roll_link" file="r_ankle_roll_link.STL"/>
  </asset>

  <worldbody>
    <light directional="true" diffuse=".4 .4 .4" specular="0.1 0.1 0.1" pos="0 0 5.0" dir="0 0 -1" castshadow="false"/>
    <light directional="true" diffuse=".6 .6 .6" specular="0.2 0.2 0.2" pos="0 0 4" dir="0 0 -1"/>
    <geom name="ground" type="plane" size="0 0 1" pos="0.001 0 0" quat="1 0 0 0" material="matplane" condim="1" conaffinity="15"/>

    <body name="base_link" pos="0 0 0.55">
      <inertial pos="1.254094e-03 -2.171701e-03 4.494330e-02" mass="1.914587e+00" fullinertia="4.581786e-03 2.116897e-03 4.196393e-03 -1.102273e-05 -6.894191e-06 -2.899742e-05"/>
      <freejoint name="root"/>
      <site name="imu" size="0.01" pos="0.0 0 0.0"/>
      <geom type="mesh" rgba="0.792157 0.819608 0.933333 1" mesh="base_link"/>
      <body name="waist_yaw_link" pos="0 0 0.129049999999987">
        <inertial pos="-4.378868e-03 -6.672295e-03 1.240299e-01" mass="5.271670e+00" fullinertia="5.482801e-02 4.887115e-02 1.609058e-02 6.175213e-05 -1.957883e-03 1.033938e-03"/>
        <joint name="waist_yaw_joint" type="hinge" axis="0 0 -1" limited="true" range="-1.57 1.57"/>
        <geom type="mesh" rgba="0.792157 0.819608 0.933333 1" mesh="waist_yaw_link"/>
        <body name="l_arm_pitch_link" pos="0.0010007 0.083723 0.17204" quat="0.9914448214 0.1305264957 0 0">
          <inertial pos="1.956958e-03 4.005473e-02 1.480389e-05" mass="3.228282e-01" fullinertia="1.602346e-04 1.550148e-04 1.688444e-04 -2.179800e-06 -4.922125e-07 1.210814e-06"/>
          <joint name="l_arm_pitch_joint" type="hinge" axis="0 1 0" limited="true" range="-3.14 1.57"/>
          <geom type="mesh" rgba="0.498039 0.498039 0.498039 1" mesh="l_arm_pitch_link"/>
          <body name="l_arm_roll_link" pos="-0.0010007 0.044 0" quat="0.9914448214 -0.1305264957 0 0">
            <inertial pos="3.495797e-04 1.900254e-02 -5.207819e-02" mass="3.834243e-01" fullinertia="4.321869e-04 4.873103e-04 2.473135e-04 -1.276022e-06 5.376326e-06 3.726497e-05"/>
            <joint name="l_arm_roll_joint" type="hinge" axis="1 0 0" limited="true" range="-1.04 1.4"/>
            <geom type="mesh" rgba="0.498039 0.498039 0.498039 1" mesh="l_arm_roll_link"/>
            <body name="l_arm_yaw_link" pos="0.0010007 0.023135 -0.092344" quat="0.9990482317 0.04361915629 0 0">
              <inertial pos="7.083462e-03 -9.665339e-04 -5.421378e-02" mass="3.366217e-01" fullinertia="2.023561e-04 1.986222e-04 1.466206e-04 1.216495e-06 2.517202e-05 -2.404022e-06"/>
              <joint name="l_arm_yaw_joint" type="hinge" axis="0 0 1" limited="true" range="-1.57 1.57"/>
              <geom type="mesh" rgba="0.498039 0.498039 0.498039 1" mesh="l_arm_yaw_link"/>
              <body name="l_elbow_pitch_link" pos="0.010308 0 -0.061252">
                <inertial pos="-6.099702e-05 1.264798e-03 -8.935936e-02" mass="3.291803e-01" fullinertia="1.099657e-03 1.077996e-03 1.519028e-04 2.269078e-06 2.111167e-05 -1.111900e-05"/>
                <joint name="l_elbow_pitch_joint" type="hinge" axis="0 1 0" limited="true" range="-2.26 0"/>
                <geom type="mesh" rgba="0.498039 0.498039 0.498039 1" mesh="l_elbow_pitch_link"/>
              </body>
            </body>
          </body>
        </body>
        <body name="r_arm_pitch_link" pos="0.0010007 -0.083723 0.17204" quat="0.9914448214 -0.1305264957 0 0">
          <inertial pos="1.956958e-03 -4.005473e-02 1.480389e-05" mass="3.228282e-01" fullinertia="1.602346e-04 1.550148e-04 1.688444e-04 2.179800e-06 -4.922125e-07 -1.210814e-06"/>
          <joint name="r_arm_pitch_joint" type="hinge" axis="0 1 0" limited="true" range="-3.14 1.57"/>
          <geom type="mesh" rgba="1 1 1 1" mesh="r_arm_pitch_link"/>
          <body name="r_arm_roll_link" pos="-0.0010007 -0.044 0" quat="0.9914448214 0.1305264957 0 0">
            <inertial pos="3.495797e-04 -1.900254e-02 -5.207819e-02" mass="3.834243e-01" fullinertia="4.321869e-04 4.873103e-04 2.473135e-04 1.276022e-06 5.376326e-06 -3.726497e-05"/>
            <joint name="r_arm_roll_joint" type="hinge" axis="1 0 0" limited="true" range="-1.4 1.04"/>
            <geom type="mesh" rgba="1 1 1 1" mesh="r_arm_roll_link"/>
            <body name="r_arm_yaw_link" pos="0.0010007 -0.023135 -0.092344" quat="0.9990482317 -0.04361915629 0 0">
              <inertial pos="7.083462e-03 9.665339e-04 -5.421378e-02" mass="3.366217e-01" fullinertia="2.023561e-04 1.986222e-04 1.466206e-04 -1.216495e-06 2.517202e-05 2.404022e-06"/>
              <joint name="r_arm_yaw_joint" type="hinge" axis="0 0 1" limited="true" range="-1.57 1.57"/>
              <geom type="mesh" rgba="1 1 1 1" mesh="r_arm_yaw_link"/>
              <body name="r_elbow_pitch_link" pos="0.010308 0 -0.061252">
                <inertial pos="-6.099702e-05 -1.264798e-03 -8.935936e-02" mass="3.291803e-01" fullinertia="1.099657e-03 1.077996e-03 1.519028e-04 -2.269078e-06 2.111167e-05 1.111900e-05"/>
                <joint name="r_elbow_pitch_joint" type="hinge" axis="0 1 0" limited="true" range="-2.26 0"/>
                <geom type="mesh" rgba="1 1 1 1" mesh="r_elbow_pitch_link"/>
              </body>
            </body>
          </body>
        </body>
      </body>
      <body name="l_leg_pitch_link" pos="0.0010184 0.1 0.03875">
        <inertial pos="2.342006e-03 -6.288304e-03 -5.508908e-02" mass="9.524865e-01" fullinertia="1.273898e-03 1.477467e-03 9.547527e-04 -1.905193e-05 2.262007e-05 2.314745e-04"/>
        <joint name="l_leg_pitch_joint" type="hinge" axis="0 1 0" limited="true" range="-2.09 2.09"/>
        <geom type="mesh" rgba="1 1 1 1" mesh="l_leg_pitch_link"/>
        <body name="l_leg_roll_link" pos="0 0 -0.0665">
          <inertial pos="8.630926e-04 -4.348477e-05 -6.783584e-02" mass="7.938022e-01" fullinertia="1.413319e-03 1.730174e-03 9.765278e-04 -1.731471e-06 7.649985e-06 9.611243e-07"/>
          <joint name="l_leg_roll_joint" type="hinge" axis="1 0 0" limited="true" range="-0.66 1.57"/>
          <geom type="mesh" rgba="1 1 1 1" mesh="l_leg_roll_link"/>
          <body name="l_leg_yaw_link" pos="0 0 -0.098">
            <inertial pos="2.930961e-03 -4.613711e-04 -8.575024e-02" mass="1.100959e+00" fullinertia="1.431833e-03 1.330397e-03 8.199494e-04 -3.317458e-06 -9.003192e-05 -9.732365e-06"/>
            <joint name="l_leg_yaw_joint" type="hinge" axis="0 0 1" limited="true" range="-2.53 2.53"/>
            <geom type="mesh" rgba="1 1 1 1" mesh="l_leg_yaw_link"/>
            <body name="l_knee_pitch_link" pos="0 0 -0.101">
              <inertial pos="8.215739e-03 4.304640e-04 -9.217458e-02" mass="1.529376e+00" fullinertia="5.317183e-03 5.286131e-03 1.657590e-03 -1.077991e-05 -1.574639e-04 -7.527479e-05"/>
              <joint name="l_knee_pitch_joint" type="hinge" axis="0 1 0" limited="true" range="0 2.24"/>
              <geom type="mesh" rgba="1 1 1 1" mesh="l_knee_pitch_link"/>
              <body name="l_ankle_pitch_link" pos="0.00066801 -0.0005 -0.20237">
                <inertial pos="-1.670842e-04 1.926440e-03 8.725702e-04" mass="8.652074e-02" fullinertia="1.155771e-05 1.329746e-05 1.260103e-05 -2.785339e-08 -1.345344e-08 1.792311e-07"/>
                <joint name="l_ankle_pitch_joint" type="hinge" axis="0 1 0" limited="true" range="-0.96 0.44"/>
                <geom type="mesh" rgba="1 1 1 1" mesh="l_ankle_pitch_link"/>
                <body name="l_ankle_roll_link" pos="0 0 0">
                  <inertial pos="2.015496e-02 -2.532183e-05 -2.690058e-02" mass="6.921412e-01" fullinertia="4.196112e-04 1.862454e-03 2.032621e-03 -4.653248e-07 3.100447e-05 -2.272900e-07"/>
                  <joint name="l_ankle_roll_joint" type="hinge" axis="1 0 0" limited="true" range="-0.17 0.17"/>
                  <geom type="mesh" rgba="1 1 1 1" mesh="l_ankle_roll_link"/>
                </body>
              </body>
            </body>
          </body>
        </body>
      </body>
      <body name="r_leg_pitch_link" pos="0.0010184 -0.1 0.03875">
        <inertial pos="2.342006e-03 6.288304e-03 -5.508908e-02" mass="9.524865e-01" fullinertia="1.273898e-03 1.477467e-03 9.547527e-04 1.905193e-05 2.262007e-05 -2.314745e-04"/>
        <joint name="r_leg_pitch_joint" type="hinge" axis="0 1 0" limited="true" range="-2.09 2.09"/>
        <geom type="mesh" rgba="1 1 1 1" mesh="r_leg_pitch_link"/>
        <body name="r_leg_roll_link" pos="0 0 -0.0665">
          <inertial pos="8.630926e-04 4.348477e-05 -6.783584e-02" mass="7.938022e-01" fullinertia="1.413319e-03 1.730174e-03 9.765278e-04 1.731471e-06 7.649985e-06 -9.611243e-07"/>
          <joint name="r_leg_roll_joint" type="hinge" axis="1 0 0" limited="true" range="-1.57 0.66"/>
          <geom type="mesh" rgba="1 1 1 1" mesh="r_leg_roll_link"/>
          <body name="r_leg_yaw_link" pos="0 0 -0.098">
            <inertial pos="2.930961e-03 4.613711e-04 -8.575024e-02" mass="1.100959e+00" fullinertia="1.431833e-03 1.330397e-03 8.199494e-04 3.317458e-06 -9.003192e-05 9.732365e-06"/>
            <joint name="r_leg_yaw_joint" type="hinge" axis="0 0 1" limited="true" range="-2.53 2.53"/>
            <geom type="mesh" rgba="1 1 1 1" mesh="r_leg_yaw_link"/>
            <body name="r_knee_pitch_link" pos="0 0 -0.101">
              <inertial pos="8.215739e-03 -4.304640e-04 -9.217458e-02" mass="1.529376e+00" fullinertia="5.317183e-03 5.286131e-03 1.657590e-03 1.077991e-05 -1.574639e-04 7.527479e-05"/>
              <joint name="r_knee_pitch_joint" type="hinge" axis="0 1 0" limited="true" range="0 2.24"/>
              <geom type="mesh" rgba="1 1 1 1" mesh="r_knee_pitch_link"/>
              <body name="r_ankle_pitch_link" pos="0.00066801 0.0005 -0.20237">
                <inertial pos="-1.670842e-04 -1.926440e-03 8.725702e-04" mass="8.652074e-02" fullinertia="1.155771e-05 1.329746e-05 1.260103e-05 2.785339e-08 -1.345344e-08 -1.792311e-07"/>
                <joint name="r_ankle_pitch_joint" type="hinge" axis="0 1 0" limited="true" range="-0.96 0.44"/>
                <geom type="mesh" rgba="1 1 1 1" mesh="r_ankle_pitch_link"/>
                <body name="r_ankle_roll_link" pos="0 0 0">
                  <inertial pos="2.015496e-02 2.532183e-05 -2.690058e-02" mass="6.921412e-01" fullinertia="4.196112e-04 1.862454e-03 2.032621e-03 4.653248e-07 3.100447e-05 2.272900e-07"/>
                  <joint name="r_ankle_roll_joint" type="hinge" axis="1 0 0" limited="true" range="-0.17 0.17"/>
                  <geom type="mesh" rgba="1 1 1 1" mesh="r_ankle_roll_link"/>
                </body>
              </body>
            </body>
          </body>
        </body>
      </body>
    </body>
  </worldbody>

  <actuator>
    <motor name="waist_yaw_joint" joint="waist_yaw_joint" gear="1" ctrllimited="true" ctrlrange="-200 200"/>
    <motor name="l_arm_pitch_joint" joint="l_arm_pitch_joint" gear="1" ctrllimited="true" ctrlrange="-200 200"/>
    <motor name="l_arm_roll_joint" joint="l_arm_roll_joint" gear="1" ctrllimited="true" ctrlrange="-200 200"/>
    <motor name="l_arm_yaw_joint" joint="l_arm_yaw_joint" gear="1" ctrllimited="true" ctrlrange="-200 200"/>
    <motor name="l_elbow_pitch_joint" joint="l_elbow_pitch_joint" gear="1" ctrllimited="true" ctrlrange="-200 200"/>
    <motor name="r_arm_pitch_joint" joint="r_arm_pitch_joint" gear="1" ctrllimited="true" ctrlrange="-200 200"/>
    <motor name="r_arm_roll_joint" joint="r_arm_roll_joint" gear="1" ctrllimited="true" ctrlrange="-200 200"/>
    <motor name="r_arm_yaw_joint" joint="r_arm_yaw_joint" gear="1" ctrllimited="true" ctrlrange="-200 200"/>
    <motor name="r_elbow_pitch_joint" joint="r_elbow_pitch_joint" gear="1" ctrllimited="true" ctrlrange="-200 200"/>
    <motor name="l_leg_pitch_joint" joint="l_leg_pitch_joint" gear="1" ctrllimited="true" ctrlrange="-200 200"/>
    <motor name="l_leg_roll_joint" joint="l_leg_roll_joint" gear="1" ctrllimited="true" ctrlrange="-200 200"/>
    <motor name="l_leg_yaw_joint" joint="l_leg_yaw_joint" gear="1" ctrllimited="true" ctrlrange="-200 200"/>
    <motor name="l_knee_pitch_joint" joint="l_knee_pitch_joint" gear="1" ctrllimited="true" ctrlrange="-200 200"/>
    <motor name="l_ankle_pitch_joint" joint="l_ankle_pitch_joint" gear="1" ctrllimited="true" ctrlrange="-200 200"/>
    <motor name="l_ankle_roll_joint" joint="l_ankle_roll_joint" gear="1" ctrllimited="true" ctrlrange="-200 200"/>
    <motor name="r_leg_pitch_joint" joint="r_leg_pitch_joint" gear="1" ctrllimited="true" ctrlrange="-200 200"/>
    <motor name="r_leg_roll_joint" joint="r_leg_roll_joint" gear="1" ctrllimited="true" ctrlrange="-200 200"/>
    <motor name="r_leg_yaw_joint" joint="r_leg_yaw_joint" gear="1" ctrllimited="true" ctrlrange="-200 200"/>
    <motor name="r_knee_pitch_joint" joint="r_knee_pitch_joint" gear="1" ctrllimited="true" ctrlrange="-200 200"/>
    <motor name="r_ankle_pitch_joint" joint="r_ankle_pitch_joint" gear="1" ctrllimited="true" ctrlrange="-200 200"/>
    <motor name="r_ankle_roll_joint" joint="r_ankle_roll_joint" gear="1" ctrllimited="true" ctrlrange="-200 200"/>
  </actuator>

  <sensor>
    <framequat name="orientation" objtype="site" noise="0.001" objname="imu"/>
    <framepos name="position" objtype="site" noise="0.001" objname="imu"/>
    <gyro name="angular-velocity" site="imu" noise="0.005" cutoff="34.9"/>
    <velocimeter name="linear-velocity" site="imu" noise="0.001" cutoff="30"/>
    <accelerometer name="linear-acceleration" site="imu" noise="0.005" cutoff="157"/>
    <magnetometer name="magnetometer" site="imu"/>
  </sensor>
</mujoco>
